Workbook

Sheet Bảng sản phẩm
A1: BẢNG HÀNG HÓA
A2: Stt | B2: Mã Sản phẩm | C2: Tên sản phẩm | D2: Đơn vị tính | E2: Đơn giá | F2: Hình ảnh
A3: GIẤY IN , GIẤY PHOTO , BÌA CÁC LOẠI
A4: 1 | B4: a1 | C4: Giấy Double A A4 ĐL70 | D4: Ream | E4: 531100
A5: 2 | B5: a2 | C5: Giấy IK Plus A4 ĐL70 | D5: Ream | E5: 5564
A6: 3 | B6: a3 | C6: Giấy Paper One A4 ĐL 70 | D6: Ream | E6: 5564
A7: 4 | B7: a4 | C7: Giấy A4 Acura ĐL 70gsm | D7: Ream | E7: 5564
A8: 5 | B8: a5 | C8: Giấy A4 Acura Plus ĐL 70gsm | D8: Ream | E8: 5564
A9: 6 | B9: a6 | C9: Giấy A4 Qualiti A4 80/90gms | D9: Ream | E9: 5564
A10: 7 | B10: a7 | C10: Giấy A4 IK Copy 65/90 | D10: Ream | E10: 5564
A11: 8 | B11: a8 | C11: Giấy A4 Copy One A4 80gsm | D11: Ream | E11: 5564
A12: 9 | B12: a9 | C12: Giấy Smartis A4 | D12: Ream | E12: 5564
A13: 10 | B13: a10 | C13: Giấy quality A4 ĐL 70 | D13: Ream
A14: 11 | B14: a11 | C14: Giấy Green Pine A4 70gms | D14: Ream
A15: 12 | B15: a12 | C15: Giấy IK one A4 70/90 | D15: Ream
A16: 13 | B16: a13 | C16: Giấy Epaper A4 70/90 | D16: Ream
A17: 14 | B17: a14 | C17: Giấy Green Pine A4 65 gms | D17: Ream
A18: 15 | B18: a15 | C18: Giấy Green A4 73gms | D18: Ream
A19: 16 | B19: a16 | C19: Giấy Bãi Bằng A4 | D19: Ream
A20: 17 | B20: a17 | C20: Giấy in A4 Paper One ĐL 80 gsm | D20: Ream
A21: 18 | C21: Giấy in A4 Double A ĐL80gsm | D21: Ream
A22: 19 | C22: Giấy A4 An Hòa ĐL 70gsm ( Màng co ) | D22: Ream
A23: 20 | C23: Giấy A3 Green Pine 70gsm | D23: Ream
A24: 21 | C24: Giấy A3 King 100 70gsm | D24: Ream
A25: 22 | C25: Giấy in A3 IK 70gms | D25: Ream
A26: 23 | C26: Giấy in A3 Paper One ĐL 70gsm | D26: Ream
A27: 24 | C27: Giấy in A3 Double A ĐL 70gram | D27: Ream
A28: 25 | C28: Giấy A5 Double A 70gsm | D28: Ream
A29: 26 | C29: Giấy A5 Ik plus 70gsm | D29: Ream
A30: 27 | C30: Giấy A5 Green 70gsm | D30: Ream
A31: 28 | C31: Giấy FAST COPY 70 | D31: Ream
A32: 29 | C32: Giấy Golden Star A4 70gsm | D32: Ream
... A49: 46 | C49: Giấy bìa trộn nhiều màu (1 Tập nhiều màu) | D49: Tập
A50: GIẤY IN CUỘN KHỔ LỚN
A51: 1 | C51: Giấy cuộn A0-ĐL 80 | D51: Cuộn
A52: 2 | C52: Giấy cuộn A1-ĐL 80 | D52: Cuộn
A53: 3 | C53: Giấy cuộn A2-ĐL 80 | D53: Cuộn
A54: 4 | C54: Giấy cuộn A0- ĐL 100 | D54: Cuộn
A55: 5 | C55: Giấy cuộn A1- ĐL 100 | D55: Cuộn
A56: 6 | C56: Giấy cuộn A2- ĐL 100 | D56: Cuộn
...

Sheet Báo giá 
B1: CÔNG TY TNHH NK NAM KHÁNH
D2: Địa chỉ ( Address): Khu X1, Thôn Nguyên Khê - Xã Phúc Thịnh - TP.Hà Nội
D3: Mã số thuế : 0108910572
D4: Số điện thoại : 0766.088.886 - Gmail : phankhanhfj@gmail.com
B5: BẢNG BÁO GIÁ
B6: Số : BG00001
B7: Ngày 26 tháng 02 năm 2026
B8: Kính gửi | D8: CÔNG TY TNHH SD VIỆT NAM
B9: Người đại diện :
B10: Số điện thoại
B11: Địa chỉ : Lô H2a, khu công nghiệp Thăng Long, Xã Thiên Lộc, TP Hà Nội, Việt Nam
B12: Công ty TNHH NK Nam Khánh xin gửi tới quý Công ty bảng báo giá mặt hàng sau
G13: Loại tiền/ Vnđ
B14: Stt | C14: Mã hàng | D14: Tên hàng hóa, dịch vụ | E14: Đơn vị tính | F14: Số lượng | G14: Đơn giá | H14: Thành tiền
B15: 1 | C15: a1 | D15: =IFERROR(VLOOKUP(C15,'Bảng sản phẩm'!$B$4:$D$981,2,0),0) -> Giấy Double A A4 ĐL70 | E15: =IFERROR(VLOOKUP(C15,'Bảng sản phẩm'!$B$4:$G$981,3,0),0) -> Ream | F15: 1 | G15: =IFERROR(VLOOKUP(C15,'Bảng sản phẩm'!$B$4:$G$981,4,0),0) -> 531100 | H15: =+F15*G15 -> 531100
B16: 2 | C16: a2 | D16: =IFERROR(VLOOKUP(C16,'Bảng sản phẩm'!$B$4:$D$981,2,0),0) -> Giấy IK Plus A4 ĐL70 | E16: =IFERROR(VLOOKUP(C16,'Bảng sản phẩm'!$B$4:$G$981,3,0),0) -> Ream | F16: 5 | G16: =IFERROR(VLOOKUP(C16,'Bảng sản phẩm'!$B$4:$G$981,4,0),0) -> 5564 | H16: =+F16*G16 -> 27820
B17: 3 | C17: a3 | D17: =IFERROR(VLOOKUP(C17,'Bảng sản phẩm'!$B$4:$D$981,2,0),0) -> Giấy Paper One A4 ĐL 70 | E17: =IFERROR(VLOOKUP(C17,'Bảng sản phẩm'!$B$4:$G$981,3,0),0) -> Ream | F17: 5 | G17: =IFERROR(VLOOKUP(C17,'Bảng sản phẩm'!$B$4:$G$981,4,0),0) -> 5564 | H17: =+F17*G17 -> 27820
B18: 4 | C18: a4 | D18: =IFERROR(VLOOKUP(C18,'Bảng sản phẩm'!$B$4:$D$981,2,0),0) -> Giấy A4 Acura ĐL 70gsm | E18: =IFERROR(VLOOKUP(C18,'Bảng sản phẩm'!$B$4:$G$981,3,0),0) -> Ream | F18: 5 | G18: =IFERROR(VLOOKUP(C18,'Bảng sản phẩm'!$B$4:$G$981,4,0),0) -> 5564 | H18: =+F18*G18 -> 27820
B19: 5 | C19: a5 | D19: =IFERROR(VLOOKUP(C19,'Bảng sản phẩm'!$B$4:$D$981,2,0),0) -> Giấy A4 Acura Plus ĐL 70gsm | E19: =IFERROR(VLOOKUP(C19,'Bảng sản phẩm'!$B$4:$G$981,3,0),0) -> Ream | F19: 5 | G19: =IFERROR(VLOOKUP(C19,'Bảng sản phẩm'!$B$4:$G$981,4,0),0) -> 5564 | H19: =+F19*G19 -> 27820
B20: 6 | C20: a6 | D20: =IFERROR(VLOOKUP(C20,'Bảng sản phẩm'!$B$4:$D$981,2,0),0) -> Giấy A4 Qualiti A4 80/90gms | E20: =IFERROR(VLOOKUP(C20,'Bảng sản phẩm'!$B$4:$G$981,3,0),0) -> Ream | F20: 5 | G20: =IFERROR(VLOOKUP(C20,'Bảng sản phẩm'!$B$4:$G$981,4,0),0) -> 5564 | H20: =+F20*G20 -> 27820
B21: 7 | C21: a7 | D21: =IFERROR(VLOOKUP(C21,'Bảng sản phẩm'!$B$4:$D$981,2,0),0) -> Giấy A4 IK Copy 65/90 | E21: =IFERROR(VLOOKUP(C21,'Bảng sản phẩm'!$B$4:$G$981,3,0),0) -> Ream | F21: 5 | G21: =IFERROR(VLOOKUP(C21,'Bảng sản phẩm'!$B$4:$G$981,4,0),0) -> 5564 | H21: =+F21*G21 -> 27820
B22: 8 | C22: a8 | D22: =IFERROR(VLOOKUP(C22,'Bảng sản phẩm'!$B$4:$D$981,2,0),0) -> Giấy A4 Copy One A4 80gsm | E22: =IFERROR(VLOOKUP(C22,'Bảng sản phẩm'!$B$4:$G$981,3,0),0) -> Ream | F22: 5 | G22: =IFERROR(VLOOKUP(C22,'Bảng sản phẩm'!$B$4:$G$981,4,0),0) -> 5564 | H22: =+F22*G22 -> 27820
B23: 9 | C23: a9 | D23: =IFERROR(VLOOKUP(C23,'Bảng sản phẩm'!$B$4:$D$981,2,0),0) -> Giấy Smartis A4 | E23: =IFERROR(VLOOKUP(C23,'Bảng sản phẩm'!$B$4:$G$981,3,0),0) -> Ream | F23: 5 | G23: =IFERROR(VLOOKUP(C23,'Bảng sản phẩm'!$B$4:$G$981,4,0),0) -> 5564 | H23: =+F23*G23 -> 27820
B24: 10 | C24: a10 | D24: =IFERROR(VLOOKUP(C24,'Bảng sản phẩm'!$B$4:$D$981,2,0),0) -> Giấy quality A4 ĐL 70 | E24: =IFERROR(VLOOKUP(C24,'Bảng sản phẩm'!$B$4:$G$981,3,0),0) -> Ream | F24: 5 | G24: =IFERROR(VLOOKUP(C24,'Bảng sản phẩm'!$B$4:$G$981,4,0),0) -> 0 | H24: =+F24*G24 -> 0
B25: 11 | C25: a11 | D25: =IFERROR(VLOOKUP(C25,'Bảng sản phẩm'!$B$4:$D$981,2,0),0) -> Giấy Green Pine A4 70gms | E25: =IFERROR(VLOOKUP(C25,'Bảng sản phẩm'!$B$4:$G$981,3,0),0) -> Ream | F25: 5 | G25: =IFERROR(VLOOKUP(C25,'Bảng sản phẩm'!$B$4:$G$981,4,0),0) -> 0 | H25: =+F25*G25 -> 0
B26: 12 | C26: a12 | D26: =IFERROR(VLOOKUP(C26,'Bảng sản phẩm'!$B$4:$D$981,2,0),0) -> Giấy IK one A4 70/90 | E26: =IFERROR(VLOOKUP(C26,'Bảng sản phẩm'!$B$4:$G$981,3,0),0) -> Ream | F26: 5 | G26: =IFERROR(VLOOKUP(C26,'Bảng sản phẩm'!$B$4:$G$981,4,0),0) -> 0 | H26: =+F26*G26 -> 0
B27: 13 | D27: =IFERROR(VLOOKUP(C27,'Bảng sản phẩm'!$B$4:$D$981,2,0),0) -> 0 | E27: =IFERROR(VLOOKUP(C27,'Bảng sản phẩm'!$B$4:$G$981,3,0),0) -> 0 | F27: 5 | G27: =IFERROR(VLOOKUP(C27,'Bảng sản phẩm'!$B$4:$G$981,4,0),0) -> 0 | H27: =+F27*G27 -> 0
B28: 14 | D28: =IFERROR(VLOOKUP(C28,'Bảng sản phẩm'!$B$4:$D$981,2,0),0) -> 0 | E28: =IFERROR(VLOOKUP(C28,'Bảng sản phẩm'!$B$4:$G$981,3,0),0) -> 0 | F28: 5 | G28: =IFERROR(VLOOKUP(C28,'Bảng sản phẩm'!$B$4:$G$981,4,0),0) -> 0 | H28: =+F28*G28 -> 0
B29: 15 | D29: =IFERROR(VLOOKUP(C29,'Bảng sản phẩm'!$B$4:$D$981,2,0),0) -> 0 | E29: =IFERROR(VLOOKUP(C29,'Bảng sản phẩm'!$B$4:$G$981,3,0),0) -> 0 | F29: 5 | G29: =IFERROR(VLOOKUP(C29,'Bảng sản phẩm'!$B$4:$G$981,4,0),0) -> 0 | H29: =+F29*G29 -> 0
B30: 16 | D30: =IFERROR(VLOOKUP(C30,'Bảng sản phẩm'!$B$4:$D$981,2,0),0) -> 0 | E30: =IFERROR(VLOOKUP(C30,'Bảng sản phẩm'!$B$4:$G$981,3,0),0) -> 0 | G30: =IFERROR(VLOOKUP(C30,'Bảng sản phẩm'!$B$4:$G$981,4,0),0) -> 0 | H30: =+F30*G30 -> 0
B31: 17 | D31: =IFERROR(VLOOKUP(C31,'Bảng sản phẩm'!$B$4:$D$981,2,0),0) -> 0 | E31: =IFERROR(VLOOKUP(C31,'Bảng sản phẩm'!$B$4:$G$981,3,0),0) -> 0 | G31: =IFERROR(VLOOKUP(C31,'Bảng sản phẩm'!$B$4:$G$981,4,0),0) -> 0 | H31: =+F31*G31 -> 0
B32: 18 | D32: =IFERROR(VLOOKUP(C32,'Bảng sản phẩm'!$B$4:$D$981,2,0),0) -> 0 | E32: =IFERROR(VLOOKUP(C32,'Bảng sản phẩm'!$B$4:$G$981,3,0),0) -> 0 | G32: =IFERROR(VLOOKUP(C32,'Bảng sản phẩm'!$B$4:$G$981,4,0),0) -> 0 | H32: =+F32*G32 -> 0
B33: 19 | D33: =IFERROR(VLOOKUP(C33,'Bảng sản phẩm'!$B$4:$D$981,2,0),0) -> 0 | E33: =IFERROR(VLOOKUP(C33,'Bảng sản phẩm'!$B$4:$G$981,3,0),0) -> 0 | G33: =IFERROR(VLOOKUP(C33,'Bảng sản phẩm'!$B$4:$G$981,4,0),0) -> 0 | H33: =+F33*G33 -> 0
B34: 20 | D34: =IFERROR(VLOOKUP(C34,'Bảng sản phẩm'!$B$4:$D$981,2,0),0) -> 0 | E34: =IFERROR(VLOOKUP(C34,'Bảng sản phẩm'!$B$4:$G$981,3,0),0) -> 0 | G34: =IFERROR(VLOOKUP(C34,'Bảng sản phẩm'!$B$4:$G$981,4,0),0) -> 0 | H34: =+F34*G34 -> 0
B35: 21 | D35: =IFERROR(VLOOKUP(C35,'Bảng sản phẩm'!$B$4:$D$981,2,0),0) -> 0 | E35: =IFERROR(VLOOKUP(C35,'Bảng sản phẩm'!$B$4:$G$981,3,0),0) -> 0 | G35: =IFERROR(VLOOKUP(C35,'Bảng sản phẩm'!$B$4:$G$981,4,0),0) -> 0 | H35: =+F35*G35 -> 0
B36: 22 | E36: =IFERROR(VLOOKUP(C36,'Bảng sản phẩm'!$B$4:$G$981,3,0),0) -> 0 | G36: =IFERROR(VLOOKUP(C36,'Bảng sản phẩm'!$B$4:$G$981,4,0),0) -> 0 | H36: =+F36*G36 -> 0
B37: Tổng cộng tiền hàng | H37: =SUM(H15:H36) -> 753660
B38: Thuế VAT | D38: 0.08 | H38: =+H37*D38 -> 60292.8
B39: Tổng tiền thanh toán | H39: =+H38+H37 -> 813952.8
B40: Bằng chữ : | D40: {=[1]!vnd(H39)} -> Tám trăm mười ba nghìn, chín trăm năm mươi ba đồng chẵn.
...

Sheet Đơn hàng
B1: CÔNG TY TNHH NK NAM KHÁNH
D2: Địa chỉ ( Address): Khu X1, Thôn Nguyên Khê - Xã Phúc Thịnh - TP.Hà Nội
D3: Mã số thuế : 0108910572
D4: Số điện thoại : 0766.088.886 - Gmail : phankhanhfj@gmail.com
D5: ĐƠN HÀNG
D6: Số : DH00001
B7: Ngày 26 tháng 02 năm 2026
B8: Kính gửi | D8: CÔNG TY TNHH SD VIỆT NAM
B9: Người đại diện :
B10: Số điện thoại
B11: Địa chỉ : Lô H2a, khu công nghiệp Thăng Long, Xã Thiên Lộc, TP Hà Nội, Việt Nam
B12: Công ty TNHH NK Nam Khánh xin gửi tới quý Công ty bảng đơn hàng sau
G13: Loại tiền/ Vnđ
B14: Stt | C14: Mã hàng | D14: Tên hàng hóa, dịch vụ | E14: Đơn vị tính | F14: Số lượng | G14: Đơn giá | H14: Thành tiền
B15: 1 | C15: a1 | D15: =IFERROR(VLOOKUP(C15,'Bảng sản phẩm'!$B$4:$D$981,2,0),0) -> Giấy Double A A4 ĐL70 | E15: =IFERROR(VLOOKUP(C15,'Bảng sản phẩm'!$B$4:$G$981,3,0),0) -> Ream | F15: 1 | G15: =IFERROR(VLOOKUP(C15,'Bảng sản phẩm'!$B$4:$G$981,4,0),0) -> 531100 | H15: =+F15*G15 -> 531100
B16: 2 | C16: a2 | D16: =IFERROR(VLOOKUP(C16,'Bảng sản phẩm'!$B$4:$D$981,2,0),0) -> Giấy IK Plus A4 ĐL70 | E16: =IFERROR(VLOOKUP(C16,'Bảng sản phẩm'!$B$4:$G$981,3,0),0) -> Ream | F16: 5 | G16: =IFERROR(VLOOKUP(C16,'Bảng sản phẩm'!$B$4:$G$981,4,0),0) -> 5564 | H16: =+F16*G16 -> 27820
B17: 3 | C17: a3 | D17: =IFERROR(VLOOKUP(C17,'Bảng sản phẩm'!$B$4:$D$981,2,0),0) -> Giấy Paper One A4 ĐL 70 | E17: =IFERROR(VLOOKUP(C17,'Bảng sản phẩm'!$B$4:$G$981,3,0),0) -> Ream | F17: 5 | G17: =IFERROR(VLOOKUP(C17,'Bảng sản phẩm'!$B$4:$G$981,4,0),0) -> 5564 | H17: =+F17*G17 -> 27820
B18: 4 | C18: a4 | D18: =IFERROR(VLOOKUP(C18,'Bảng sản phẩm'!$B$4:$D$981,2,0),0) -> Giấy A4 Acura ĐL 70gsm | E18: =IFERROR(VLOOKUP(C18,'Bảng sản phẩm'!$B$4:$G$981,3,0),0) -> Ream | F18: 5 | G18: =IFERROR(VLOOKUP(C18,'Bảng sản phẩm'!$B$4:$G$981,4,0),0) -> 5564 | H18: =+F18*G18 -> 27820
B19: 5 | C19: a5 | D19: =IFERROR(VLOOKUP(C19,'Bảng sản phẩm'!$B$4:$D$981,2,0),0) -> Giấy A4 Acura Plus ĐL 70gsm | E19: =IFERROR(VLOOKUP(C19,'Bảng sản phẩm'!$B$4:$G$981,3,0),0) -> Ream | F19: 5 | G19: =IFERROR(VLOOKUP(C19,'Bảng sản phẩm'!$B$4:$G$981,4,0),0) -> 5564 | H19: =+F19*G19 -> 27820
B20: 6 | C20: a6 | D20: =IFERROR(VLOOKUP(C20,'Bảng sản phẩm'!$B$4:$D$981,2,0),0) -> Giấy A4 Qualiti A4 80/90gms | E20: =IFERROR(VLOOKUP(C20,'Bảng sản phẩm'!$B$4:$G$981,3,0),0) -> Ream | F20: 5 | G20: =IFERROR(VLOOKUP(C20,'Bảng sản phẩm'!$B$4:$G$981,4,0),0) -> 5564 | H20: =+F20*G20 -> 27820
B21: 7 | C21: a7 | D21: =IFERROR(VLOOKUP(C21,'Bảng sản phẩm'!$B$4:$D$981,2,0),0) -> Giấy A4 IK Copy 65/90 | E21: =IFERROR(VLOOKUP(C21,'Bảng sản phẩm'!$B$4:$G$981,3,0),0) -> Ream | F21: 5 | G21: =IFERROR(VLOOKUP(C21,'Bảng sản phẩm'!$B$4:$G$981,4,0),0) -> 5564 | H21: =+F21*G21 -> 27820
B22: 8 | C22: a8 | D22: =IFERROR(VLOOKUP(C22,'Bảng sản phẩm'!$B$4:$D$981,2,0),0) -> Giấy A4 Copy One A4 80gsm | E22: =IFERROR(VLOOKUP(C22,'Bảng sản phẩm'!$B$4:$G$981,3,0),0) -> Ream | F22: 5 | G22: =IFERROR(VLOOKUP(C22,'Bảng sản phẩm'!$B$4:$G$981,4,0),0) -> 5564 | H22: =+F22*G22 -> 27820
B23: 9 | C23: a9 | D23: =IFERROR(VLOOKUP(C23,'Bảng sản phẩm'!$B$4:$D$981,2,0),0) -> Giấy Smartis A4 | E23: =IFERROR(VLOOKUP(C23,'Bảng sản phẩm'!$B$4:$G$981,3,0),0) -> Ream | F23: 5 | G23: =IFERROR(VLOOKUP(C23,'Bảng sản phẩm'!$B$4:$G$981,4,0),0) -> 5564 | H23: =+F23*G23 -> 27820
B24: 10 | C24: a10 | D24: =IFERROR(VLOOKUP(C24,'Bảng sản phẩm'!$B$4:$D$981,2,0),0) -> Giấy quality A4 ĐL 70 | E24: =IFERROR(VLOOKUP(C24,'Bảng sản phẩm'!$B$4:$G$981,3,0),0) -> Ream | F24: 5 | G24: =IFERROR(VLOOKUP(C24,'Bảng sản phẩm'!$B$4:$G$981,4,0),0) -> 0 | H24: =+F24*G24 -> 0
B25: 11 | C25: a11 | D25: =IFERROR(VLOOKUP(C25,'Bảng sản phẩm'!$B$4:$D$981,2,0),0) -> Giấy Green Pine A4 70gms | E25: =IFERROR(VLOOKUP(C25,'Bảng sản phẩm'!$B$4:$G$981,3,0),0) -> Ream | F25: 5 | G25: =IFERROR(VLOOKUP(C25,'Bảng sản phẩm'!$B$4:$G$981,4,0),0) -> 0 | H25: =+F25*G25 -> 0
B26: 12 | C26: a12 | D26: =IFERROR(VLOOKUP(C26,'Bảng sản phẩm'!$B$4:$D$981,2,0),0) -> Giấy IK one A4 70/90 | E26: =IFERROR(VLOOKUP(C26,'Bảng sản phẩm'!$B$4:$G$981,3,0),0) -> Ream | F26: 5 | G26: =IFERROR(VLOOKUP(C26,'Bảng sản phẩm'!$B$4:$G$981,4,0),0) -> 0 | H26: =+F26*G26 -> 0
B27: 13 | D27: =IFERROR(VLOOKUP(C27,'Bảng sản phẩm'!$B$4:$D$981,2,0),0) -> 0 | E27: =IFERROR(VLOOKUP(C27,'Bảng sản phẩm'!$B$4:$G$981,3,0),0) -> 0 | F27: 5 | G27: =IFERROR(VLOOKUP(C27,'Bảng sản phẩm'!$B$4:$G$981,4,0),0) -> 0 | H27: =+F27*G27 -> 0
B28: 14 | D28: =IFERROR(VLOOKUP(C28,'Bảng sản phẩm'!$B$4:$D$981,2,0),0) -> 0 | E28: =IFERROR(VLOOKUP(C28,'Bảng sản phẩm'!$B$4:$G$981,3,0),0) -> 0 | F28: 5 | G28: =IFERROR(VLOOKUP(C28,'Bảng sản phẩm'!$B$4:$G$981,4,0),0) -> 0 | H28: =+F28*G28 -> 0
B29: 15 | D29: =IFERROR(VLOOKUP(C29,'Bảng sản phẩm'!$B$4:$D$981,2,0),0) -> 0 | E29: =IFERROR(VLOOKUP(C29,'Bảng sản phẩm'!$B$4:$G$981,3,0),0) -> 0 | F29: 5 | G29: =IFERROR(VLOOKUP(C29,'Bảng sản phẩm'!$B$4:$G$981,4,0),0) -> 0 | H29: =+F29*G29 -> 0
B30: 16 | D30: =IFERROR(VLOOKUP(C30,'Bảng sản phẩm'!$B$4:$D$981,2,0),0) -> 0 | E30: =IFERROR(VLOOKUP(C30,'Bảng sản phẩm'!$B$4:$G$981,3,0),0) -> 0 | G30: =IFERROR(VLOOKUP(C30,'Bảng sản phẩm'!$B$4:$G$981,4,0),0) -> 0 | H30: =+F30*G30 -> 0
B31: 17 | D31: =IFERROR(VLOOKUP(C31,'Bảng sản phẩm'!$B$4:$D$981,2,0),0) -> 0 | E31: =IFERROR(VLOOKUP(C31,'Bảng sản phẩm'!$B$4:$G$981,3,0),0) -> 0 | G31: =IFERROR(VLOOKUP(C31,'Bảng sản phẩm'!$B$4:$G$981,4,0),0) -> 0 | H31: =+F31*G31 -> 0
B32: 18 | D32: =IFERROR(VLOOKUP(C32,'Bảng sản phẩm'!$B$4:$D$981,2,0),0) -> 0 | E32: =IFERROR(VLOOKUP(C32,'Bảng sản phẩm'!$B$4:$G$981,3,0),0) -> 0 | G32: =IFERROR(VLOOKUP(C32,'Bảng sản phẩm'!$B$4:$G$981,4,0),0) -> 0 | H32: =+F32*G32 -> 0
B33: 19 | D33: =IFERROR(VLOOKUP(C33,'Bảng sản phẩm'!$B$4:$D$981,2,0),0) -> 0 | E33: =IFERROR(VLOOKUP(C33,'Bảng sản phẩm'!$B$4:$G$981,3,0),0) -> 0 | G33: =IFERROR(VLOOKUP(C33,'Bảng sản phẩm'!$B$4:$G$981,4,0),0) -> 0 | H33: =+F33*G33 -> 0
B34: 20 | D34: =IFERROR(VLOOKUP(C34,'Bảng sản phẩm'!$B$4:$D$981,2,0),0) -> 0 | E34: =IFERROR(VLOOKUP(C34,'Bảng sản phẩm'!$B$4:$G$981,3,0),0) -> 0 | G34: =IFERROR(VLOOKUP(C34,'Bảng sản phẩm'!$B$4:$G$981,4,0),0) -> 0 | H34: =+F34*G34 -> 0
B35: 21 | D35: =IFERROR(VLOOKUP(C35,'Bảng sản phẩm'!$B$4:$D$981,2,0),0) -> 0 | E35: =IFERROR(VLOOKUP(C35,'Bảng sản phẩm'!$B$4:$G$981,3,0),0) -> 0 | G35: =IFERROR(VLOOKUP(C35,'Bảng sản phẩm'!$B$4:$G$981,4,0),0) -> 0 | H35: =+F35*G35 -> 0
B36: 22 | E36: =IFERROR(VLOOKUP(C36,'Bảng sản phẩm'!$B$4:$G$981,3,0),0) -> 0 | G36: =IFERROR(VLOOKUP(C36,'Bảng sản phẩm'!$B$4:$G$981,4,0),0) -> 0 | H36: =+F36*G36 -> 0
B37: Tổng cộng tiền hàng | H37: =SUM(H15:H36) -> 753660
B38: Thuế VAT | D38: 0.08 | H38: =+H37*D38 -> 60292.8
B39: Tổng tiền thanh toán | H39: =+H38+H37 -> 813952.8
B40: Bằng chữ : | D40: {=[1]!vnd(H39)} -> Tám trăm mười ba nghìn, chín trăm năm mươi ba đồng chẵn.
...

Sheet Lệnh xuất - BBGH
B1: CỘNG HÒA XÃ HỘI CHỦ NGHĨA VIỆT NAM
B2: Độc lập - Tự do - Hạnh Phúc
B3: BIÊN BẢN GIAO HÀNG
B4: Hôm nay ngày ........ Tháng ....... Năm 2026 tại ….................................................chúng tôi gồm có
B5: Bên A ( Bên giao hàng) : Công ty TNHH NK Nam Khánh
B6: Địa chỉ ( Address): Khu X1, Thôn Nguyên Khê - Xã Phúc Thịnh - TP.Hà Nội
B7: MST (Tax code) : 0108910572
B8: Số điện thoại ( Tel): 0766.088.886
B9: Đại diện : Ông /Bà: Nguyễn Thị Hằng Chức vụ : Thủ Kho
B10: Bên B ( Bên nhận hàng) | D10: Công ty Tnhh SDV
B11: Địa chỉ :
B12: Người đại diện….........................…..............................................................................................................................
B13: Chức vụ: …..............................................................................................…..................................................................
B14: Chúng tôi thống nhất giao và nhận hàng hóa, với quy cách, chủng loại và số lượng như sau:
B15: Stt (Sn) | C15: Mã hàng (Item Code) | D15: Tên hàng hóa, dịch vụ ( Name of goods/service) | E15: Đơn vị (Unit) | F15: Số lượng (Amount)
B16: 1 | C16: =+'Báo giá '!C15 -> a1 | D16: =+'Báo giá '!D15 -> Giấy Double A A4 ĐL70 | E16: =+'Báo giá '!E15 -> Ream | F16: =+'Báo giá '!F15 -> 1
B17: 2 | C17: =+'Báo giá '!C16 -> a2 | D17: =+'Báo giá '!D16 -> Giấy IK Plus A4 ĐL70 | E17: =+'Báo giá '!E16 -> Ream | F17: =+'Báo giá '!F16 -> 5
B18: 3 | C18: =+'Báo giá '!C17 -> a3 | D18: =+'Báo giá '!D17 -> Giấy Paper One A4 ĐL 70 | E18: =+'Báo giá '!E17 -> Ream | F18: =+'Báo giá '!F17 -> 5
B19: 4 | C19: =+'Báo giá '!C18 -> a4 | D19: =+'Báo giá '!D18 -> Giấy A4 Acura ĐL 70gsm | E19: =+'Báo giá '!E18 -> Ream | F19: =+'Báo giá '!F18 -> 5
B20: 5 | C20: =+'Báo giá '!C19 -> a5 | D20: =+'Báo giá '!D19 -> Giấy A4 Acura Plus ĐL 70gsm | E20: =+'Báo giá '!E19 -> Ream | F20: =+'Báo giá '!F19 -> 5
B21: 6 | C21: =+'Báo giá '!C20 -> a6 | D21: =+'Báo giá '!D20 -> Giấy A4 Qualiti A4 80/90gms | E21: =+'Báo giá '!E20 -> Ream | F21: =+'Báo giá '!F20 -> 5
B22: 7 | C22: =+'Báo giá '!C21 -> a7 | D22: =+'Báo giá '!D21 -> Giấy A4 IK Copy 65/90 | E22: =+'Báo giá '!E21 -> Ream | F22: =+'Báo giá '!F21 -> 5
B23: 8 | C23: =+'Báo giá '!C22 -> a8 | D23: =+'Báo giá '!D22 -> Giấy A4 Copy One A4 80gsm | E23: =+'Báo giá '!E22 -> Ream | F23: =+'Báo giá '!F22 -> 5
B24: 9 | C24: =+'Báo giá '!C23 -> a9 | D24: =+'Báo giá '!D23 -> Giấy Smartis A4 | E24: =+'Báo giá '!E23 -> Ream | F24: =+'Báo giá '!F23 -> 5
B25: 10 | C25: =+'Báo giá '!C24 -> a10 | D25: =+'Báo giá '!D24 -> Giấy quality A4 ĐL 70 | E25: =+'Báo giá '!E24 -> Ream | F25: =+'Báo giá '!F24 -> 5
B26: 11 | C26: =+'Báo giá '!C25 -> a11 | D26: =+'Báo giá '!D25 -> Giấy Green Pine A4 70gms | E26: =+'Báo giá '!E25 -> Ream | F26: =+'Báo giá '!F25 -> 5
B27: 12 | C27: =+'Báo giá '!C26 -> a12 | D27: =+'Báo giá '!D26 -> Giấy IK one A4 70/90 | E27: =+'Báo giá '!E26 -> Ream | F27: =+'Báo giá '!F26 -> 5
... B40: 25 | C40: =+'Báo giá '!C39 -> 0 | D40: =+'Báo giá '!D39 -> 0 | E40: =+'Báo giá '!E39 -> 0 | F40: =+'Báo giá '!F39 -> 0
B41: Bên B xác nhận bên A đã giao cho bên B đúng chủng loại và đủ số lượng hàng hóa như trên. Hai bên đồng ý thống nhất ký tên biên bản được lập thành 02 bản có giá trị pháp lý như nhau.
B42: Người lập Trưởng phòng KD Bên giao hàng Bên nhận hàng

Sheet Phiếu thu
A1: CÔNG TY TNHH NK NAM KHÁNH | I1: Mẫu số 01 - TT
A2: X1 Thôn Toàn Thắng, Xã Phúc Thịnh , TP.Hà Nội | I2: (Kèm theo Thông tư số 99/2025/TT-BTC ngày 27 tháng 10 năm 2025 của Bộ trưởng Bộ Tài chính)
C4: PHIẾU THU
K5: Số: | M5: PT0121
K6: Nợ: | M6: 1111
C7: Ngày 03 tháng 6 năm 2026 | K7: Có: | M7: 131
A9: Họ tên người nộp tiền: | D9: PHẠM VĂN CHUYỀN
A10: Địa chỉ: | C10: Thái Dương, Bình Giang, Hải Dương
A11: Lý do nộp: | C11: Thu tiền hàng của PHẠM VĂN CHUYỀN V0186
A12: Số tiền: | C12: 5.361.540 VND
A13: Viết bằng chữ: | C13: Năm triệu ba trăm sáu mươi mốt nghìn năm trăm bốn mươi đồng chẵn.
A14: Kèm theo số chứng từ :
A16: Tổng Giám đốc | D16: Kế toán trưởng | G16: Người nộp tiền | J16: Người lập phiếu | M16: Thủ quỹ
A17: (Ký, họ tên, đóng dấu) | D17: (Ký, họ tên) | G17: (Ký, họ tên) | J17: (Ký, họ tên) | M17: (Ký, họ tên)

Sheet Phiếu chi
A1: CÔNG TY TNHH NK NAM KHÁNH | L1: Mẫu số 02 - TT
A2: X1 Thôn Toàn thắng , Xã Phúc Thịnh, TP. Hà Nội | L2: (Kèm theo Thông tư số 99/2025/TT-BTC ngày 27 tháng 10 năm 2025 của Bộ trưởng Bộ Tài chính)
E5: PHIẾU CHI
P6: Số: | Q6: PC0197
E7: Ngày 03 tháng 7 năm 2026 | P7: Nợ: | Q7: 141
P8: Có: | Q8: 1111
A10: Họ và tên người nhận tiền: | D10: Phạm Anh Tuấn
A11: Địa chỉ:
A12: Lý do chi: | C12: Tạm ứng cho nhân viên Phạm Anh Tuấn
A13: Số tiền: | C13: 2.000.000 VND
A14: Viết bằng chữ: | C14: Hai triệu đồng chẵn.
A15: Kèm theo chứng từ số
A17: Tổng Giám đốc | F17: Kế toán trưởng | J17: Thủ quỹ | M17: Người lập phiếu | P17: Người nhận tiền
A18: (Ký, họ tên, đóng dấu) | F18: (Ký, họ tên) | J18: (Ký, họ tên) | M18: (Ký, họ tên) | P18: (Ký, họ tên)

Sheet Sheet1
